Workbook

Sheet README
A1: VILPE Sense, Vantaa warehouse: cleaned data
A3: Source | B3: 7 Excel exports from the VILPE Sense cloud service, provided by VILPE for the Vaasa Hackathon 2026
A4: What changed | B4: Finnish column names translated to English; timestamps converted to real date-time values; numbers stored as numbers; metadata collected into the Structures sheet
A5: What was NOT changed | B5: No row was removed and no measured value was altered. The Cleaning log sheet proves the row counts match the originals.
A6: Added flag columns | B6: "Duplicate of previous row" = exact repeat of an earlier row (same time and values). "Indoor/Outdoor reading missing" = sensor value blank in the original.
A7: Measurement interval | B7: About every 2 hours (hourly during the first days after installation)
A8: Abs. humidity | B8: Absolute humidity in grams of water per m³ of air, calculated by VILPE in the original export
A9: Mold index | B9: Latest value only (VILPE cloud, scale 0 to 6, alarm at 2.5). No history in the export.
A10: Data quality notes | B10: See the Data quality notes sheet for issues found during cleaning.

Sheet Structures
A1: Sheet name (original) | B1: English name | C1: Serial number | D1: Control unit | E1: Purpose | F1: Material | G1: Latest mold index | H1: Latest fan rpm | I1: Indoor sensor serial | J1: Outdoor sensor serial | K1: First reading | L1: Last reading
A2: Hallin alapohja | B2: Hall crawl space | C2: N112711X79B | D2: VILPE MCU-2 | E2: Crawl space ventilation | F2: Concrete | G2: 0.69496 | H2: 2550 | I2: P581915RH4G | J2: P582060NKD3 | K2: 45791.258 | L2: 46276.197
A3: Katto 1 | B3: Roof 1 | C3: N112741ZDLY | D3: VILPE MCU-2 | E3: Roof structure ventilation | F3: Concrete | G3: 0.00125 | H3: 1725 | I3: P485544RFGX | J3: P582028P3F8 | K3: 45790.676 | L3: 46276.204
A4: Katto 2 | B4: Roof 2 | C4: N112562K4C8 | D4: VILPE MCU-2 | E4: Roof structure ventilation | F4: Concrete | G4: 5e-05 | H4: 975 | I4: P581891D3KX | J4: P5818257GJK | K4: 45790.673 | L4: 46276.154
A5: Katto 3 | B5: Roof 3 | C5: N11251233JN | D5: VILPE MCU-2 | E5: Roof structure ventilation | F5: Concrete | G5: 0.0843 | H5: 1065 | I5: P5818844ZHT | J5: P581761Z6CY | K5: 45790.669 | L5: 46276.178
A6: Katto 4 | B6: Roof 4 | C6: N1104957TCM | D6: VILPE MCU-2 | E6: Roof structure ventilation | F6: Concrete | G6: 0.00615 | H6: 945 | I6: P524780245Z | J6: P524820YAXC | K6: 45826.755 | L6: 46276.167
A7: Viherkatto 1 | B7: Green roof 1 | C7: N1109203B9X | D7: VILPE MCU-2 | E7: Roof structure ventilation | F7: Concrete | G7: 0 | H7: 825 | I7: P482027T9DH | J7: P524996Y2AN | K7: 45790.72 | L7: 46276.183
A8: Viherkatto 2 | B8: Green roof 2 | C8: N112560ZEBX | D8: VILPE MCU-2 | E8: Roof structure ventilation | F8: Concrete | G8: 0.03095 | H8: 0 | I8: P524854LXW7 | J8: P523772RH9R | K8: 45790.676 | L8: 46276.231

Sheet Cleaning log
A1: Sheet | B1: Rows in original file | C1: Rows in this workbook | D1: Check | E1: Duplicate rows (flagged, kept) | F1: Rows with indoor reading missing | G1: Rows with outdoor reading missing
A2: Hallin alapohja | B2: 5774 | C2: =COUNTA('Hallin alapohja'!A:A)-1 | D2: =IF(B2=C2,"OK, nothing removed","MISMATCH") | E2: =COUNTIF('Hallin alapohja'!I:I,"YES") | F2: =COUNTIF('Hallin alapohja'!J:J,"YES") | G2: =COUNTIF('Hallin alapohja'!K:K,"YES")
A3: Katto 1 | B3: 5783 | C3: =COUNTA('Katto 1'!A:A)-1 | D3: =IF(B3=C3,"OK, nothing removed","MISMATCH") | E3: =COUNTIF('Katto 1'!I:I,"YES") | F3: =COUNTIF('Katto 1'!J:J,"YES") | G3: =COUNTIF('Katto 1'!K:K,"YES")
A4: Katto 2 | B4: 5792 | C4: =COUNTA('Katto 2'!A:A)-1 | D4: =IF(B4=C4,"OK, nothing removed","MISMATCH") | E4: =COUNTIF('Katto 2'!I:I,"YES") | F4: =COUNTIF('Katto 2'!J:J,"YES") | G4: =COUNTIF('Katto 2'!K:K,"YES")
A5: Katto 3 | B5: 5798 | C5: =COUNTA('Katto 3'!A:A)-1 | D5: =IF(B5=C5,"OK, nothing removed","MISMATCH") | E5: =COUNTIF('Katto 3'!I:I,"YES") | F5: =COUNTIF('Katto 3'!J:J,"YES") | G5: =COUNTIF('Katto 3'!K:K,"YES")
A6: Katto 4 | B6: 5351 | C6: =COUNTA('Katto 4'!A:A)-1 | D6: =IF(B6=C6,"OK, nothing removed","MISMATCH") | E6: =COUNTIF('Katto 4'!I:I,"YES") | F6: =COUNTIF('Katto 4'!J:J,"YES") | G6: =COUNTIF('Katto 4'!K:K,"YES")
A7: Viherkatto 1 | B7: 5785 | C7: =COUNTA('Viherkatto 1'!A:A)-1 | D7: =IF(B7=C7,"OK, nothing removed","MISMATCH") | E7: =COUNTIF('Viherkatto 1'!I:I,"YES") | F7: =COUNTIF('Viherkatto 1'!J:J,"YES") | G7: =COUNTIF('Viherkatto 1'!K:K,"YES")
A8: Viherkatto 2 | B8: 5794 | C8: =COUNTA('Viherkatto 2'!A:A)-1 | D8: =IF(B8=C8,"OK, nothing removed","MISMATCH") | E8: =COUNTIF('Viherkatto 2'!I:I,"YES") | F8: =COUNTIF('Viherkatto 2'!J:J,"YES") | G8: =COUNTIF('Viherkatto 2'!K:K,"YES")
A9: Total | B9: =SUM(B2:B8) | C9: =SUM(C2:C8) | E9: =SUM(E2:E8) | F9: =SUM(F2:F8) | G9: =SUM(G2:G8)
A11: Blue numbers = row counts read from the original VILPE files. Black = formulas counting rows in this workbook.

Sheet Data quality notes
A1: # | B1: Sheet | C1: What we noticed | D1: Evidence in the data | E1: Action taken
A2: 1 | B2: All sheets | C2: Some rows are exact repeats (same timestamp and same values) | D2: 17 rows in total, see Cleaning log | E2: Kept and flagged in column I
A3: 2 | B3: Roof 1, Green roof 1 | C3: Indoor sensor has no values for the first weeks | D3: Indoor columns blank until 18 Jun 2025 (about 420 rows each) | E3: Kept and flagged in column J
A4: 3 | B4: Hallin alapohja | C4: Indoor and outdoor sensor labels look swapped | D4: The "outdoor" sensor stays between 8 and 13 °C all year (Jan 2026 average 8.5 °C), while the "indoor" sensor follows the weather (Jan 2026 average -9.2 °C) and matches the outdoor sensors of the other 6 units (correlation 0.97) | E4: Not changed. Values kept exactly as exported. To confirm with VILPE
A5: 4 | B5: Viherkatto 2 | C5: Fan speed is 0 rpm for about 12 months | D5: 0 rpm from 13 May 2025 to 27 May 2026 (97% of all readings in the sheet) | E5: Not changed. To confirm with VILPE

Sheet Katto 1
A1: Timestamp | B1: Fan speed (rpm) | C1: Outdoor temp (°C) | D1: Outdoor RH (%) | E1: Outdoor abs. humidity (g/m³) | F1: Indoor temp (°C) | G1: Indoor RH (%) | H1: Indoor abs. humidity (g/m³) | I1: Duplicate of previous row | J1: Indoor reading missing | K1: Outdoor reading missing
A2: 45790.676 | B2: 1110 | J2: YES | K2: YES
A3: 45790.718 | B3: 1095 | J3: YES | K3: YES
A4: 45790.759 | B4: 1095 | J4: YES | K4: YES
A5: 45790.801 | B5: 1080 | J5: YES | K5: YES
A6: 45790.85 | B6: 480 | C6: 10.5 | D6: 59.1 | E6: 5.7 | J6: YES
A7: 45790.933 | B7: 495 | C7: 9.6 | D7: 64.5 | E7: 5.9 | J7: YES
A8: 45791.017 | B8: 495 | C8: 8.9 | D8: 70.8 | E8: 6.2 | J8: YES
A9: 45791.1 | B9: 495 | C9: 7.8 | D9: 75.1 | E9: 6.1 | J9: YES
A10: 45791.183 | B10: 480 | C10: 7.8 | D10: 74.6 | E10: 6.1 | J10: YES
A11: 45791.266 | B11: 480 | C11: 6.4 | D11: 69.5 | E11: 5.2 | J11: YES
A12: 45791.35 | B12: 495 | C12: 9.4 | D12: 43.7 | E12: 4 | J12: YES
A13: 45791.433 | B13: 495 | C13: 10.2 | D13: 33.6 | E13: 3.2 | J13: YES
A14: 45791.517 | B14: 510 | C14: 9.6 | D14: 37 | E14: 3.4 | J14: YES
A15: 45791.6 | B15: 495 | C15: 7 | D15: 53.5 | E15: 4.1 | J15: YES
A16: 45791.683 | B16: 495 | C16: 6.2 | D16: 65.2 | E16: 4.8 | J16: YES
A17: 45791.766 | B17: 480 | C17: 4.7 | D17: 73.7 | E17: 4.9 | J17: YES
... A424: 45826.542 | B424: 3225 | C424: 16.8 | D424: 79.1 | E424: 11.3 | J424: YES
A425: 45826.625 | B425: 1500 | C425: 15.8 | D425: 85.6 | E425: 11.5 | F425: 18.4 | G425: 72.2 | H425: 11.4
A426: 45826.708 | B426: 1575 | C426: 14.8 | D426: 79.9 | E426: 10.1 | F426: 18.9 | G426: 62.8 | H426: 10.2
A427: 45826.791 | B427: 1380 | C427: 13.7 | D427: 81 | E427: 9.6 | F427: 16.1 | G427: 68.3 | H427: 9.4
A428: 45826.874 | B428: 1395 | C428: 12.4 | D428: 78.6 | E428: 8.6 | F428: 13.9 | G428: 69.9 | H428: 8.4
A429: 45826.957 | B429: 1530 | C429: 11.6 | D429: 78 | E429: 8.1 | F429: 13.2 | G429: 71 | H429: 8.1
A430: 45827.041 | B430: 1560 | C430: 10 | D430: 82.5 | E430: 7.7 | F430: 11.4 | G430: 76.3 | H430: 7.8
A431: 45827.124 | B431: 1710 | C431: 9.6 | D431: 85.5 | E431: 7.8 | F431: 11.2 | G431: 80.5 | H431: 8.2
A432: 45827.208 | B432: 1740 | C432: 10.8 | D432: 84.6 | E432: 8.4 | F432: 12.9 | G432: 77.8 | H432: 8.8
A433: 45827.291 | B433: 1695 | C433: 13.4 | D433: 78.1 | E433: 9.1 | F433: 16.8 | G433: 65.9 | H433: 9.4
A434: 45827.374 | B434: 1575 | C434: 15.4 | D434: 69.5 | E434: 9.1 | F434: 20 | G434: 53 | H434: 9.2
A435: 45827.457 | B435: 1275 | C435: 14.5 | D435: 78.7 | E435: 9.8 | F435: 17.7 | G435: 61.8 | H435: 9.3
A436: 45827.54 | B436: 1500 | C436: 14.2 | D436: 81.1 | E436: 9.9 | F436: 16.3 | G436: 71.3 | H436: 9.9
... A605: 45841.627 | B605: 795 | C605: 20.6 | D605: 70.5 | E605: 12.6 | F605: 23 | G605: 53 | H605: 10.9
A606: 45841.627 | B606: 795 | C606: 20.6 | D606: 70.5 | E606: 12.6 | F606: 23 | G606: 53 | H606: 10.9 | I606: YES
A607: 45841.71 | B607: 1005 | C607: 18.6 | D607: 72.4 | E607: 11.5 | F607: 24.2 | G607: 47 | H607: 10.3
A608: 45841.793 | B608: 1080 | C608: 16.2 | D608: 73.1 | E608: 10.1 | F608: 19.3 | G608: 56.2 | H608: 9.3
A609: 45841.876 | B609: 1290 | C609: 13.9 | D609: 74.7 | E609: 9 | F609: 15.8 | G609: 63.7 | H609: 8.6
A610: 45841.96 | B610: 1380 | C610: 12.7 | D610: 77.4 | E610: 8.6 | F610: 15 | G610: 65.3 | H610: 8.4
A611: 45842.043 | B611: 1500 | C611: 10.7 | D611: 90.9 | E611: 8.9 | F611: 13.3 | G611: 76.8 | H611: 8.9
A612: 45842.127 | B612: 1650 | C612: 11.3 | D612: 83.1 | E612: 8.5 | F612: 12.7 | G612: 77.7 | H612: 8.6
A613: 45842.21 | B613: 1800 | C613: 15.1 | D613: 65.8 | E613: 8.5 | F613: 16.5 | G613: 63.8 | H613: 9
A614: 45842.293 | B614: 1590 | C614: 20.8 | D614: 45.8 | E614: 8.3 | F614: 22.7 | G614: 41 | H614: 8.3
...

Sheet Katto 2
A1: Timestamp | B1: Fan speed (rpm) | C1: Outdoor temp (°C) | D1: Outdoor RH (%) | E1: Outdoor abs. humidity (g/m³) | F1: Indoor temp (°C) | G1: Indoor RH (%) | H1: Indoor abs. humidity (g/m³) | I1: Duplicate of previous row | J1: Indoor reading missing | K1: Outdoor reading missing
A2: 45790.673 | B2: 1140 | J2: YES | K2: YES
A3: 45790.714 | B3: 1110 | J3: YES | K3: YES
A4: 45790.756 | B4: 1110 | J4: YES | K4: YES
A5: 45790.798 | B5: 1095 | J5: YES | K5: YES
A6: 45790.847 | B6: 750 | C6: 12.1 | D6: 47 | E6: 5 | F6: 10.9 | G6: 59.9 | H6: 6
A7: 45790.93 | B7: 945 | C7: 10.6 | D7: 56 | E7: 5.5 | F7: 9.8 | G7: 66.4 | H7: 6.2
A8: 45791.014 | B8: 945 | C8: 10.1 | D8: 60.3 | E8: 5.7 | F8: 9.2 | G8: 72.2 | H8: 6.4
A9: 45791.097 | B9: 930 | C9: 8.8 | D9: 64.5 | E9: 5.6 | F9: 8 | G9: 77.3 | H9: 6.4
A10: 45791.18 | B10: 1485 | C10: 9.6 | D10: 68 | E10: 6.2 | F10: 7.9 | G10: 77.2 | H10: 6.3
A11: 45791.264 | B11: 1425 | C11: 10.5 | D11: 54.3 | E11: 5.3 | F11: 6.7 | G11: 71.9 | H11: 5.5
A12: 45791.347 | B12: 1950 | C12: 16.3 | D12: 33 | E12: 4.6 | F12: 9.8 | G12: 46.3 | H12: 4.3
A13: 45791.431 | B13: 2310 | C13: 18.4 | D13: 24.4 | E13: 3.8 | F13: 10.4 | G13: 35.1 | H13: 3.4
A14: 45791.513 | B14: 1605 | C14: 20 | D14: 20.3 | E14: 3.5 | F14: 9.7 | G14: 38.2 | H14: 3.5
A15: 45791.597 | B15: 615 | C15: 15.7 | D15: 27.2 | E15: 3.6 | F15: 7.3 | G15: 55.5 | H15: 4.4
A16: 45791.679 | B16: 495 | C16: 10.9 | D16: 39.6 | E16: 3.9 | F16: 6.3 | G16: 68.4 | H16: 5.1
A17: 45791.763 | B17: 765 | C17: 7.5 | D17: 54.8 | E17: 4.4 | F17: 4.9 | G17: 75.8 | H17: 5.1
... A885: 45864.506 | B885: 2310 | C885: 44.3 | D885: 23.6 | E885: 14.9 | F885: 27.4 | G885: 51 | H885: 13.4
A886: 45864.506 | B886: 2310 | C886: 44.3 | D886: 23.6 | E886: 14.9 | F886: 27.4 | G886: 51 | H886: 13.4 | I886: YES
A887: 45864.589 | B887: 1650 | C887: 41.7 | D887: 24.4 | E887: 13.6 | F887: 26.9 | G887: 53.5 | H887: 13.7
A888: 45864.673 | B888: 1080 | C888: 37.1 | D888: 29.3 | E888: 12.9 | F888: 25.8 | G888: 59.8 | H888: 14.4
A889: 45864.756 | B889: 615 | C889: 29.3 | D889: 39.3 | E889: 11.5 | F889: 24.5 | G889: 65.2 | H889: 14.6
A890: 45864.84 | B890: 540 | C890: 21.7 | D890: 51.7 | E890: 9.9 | F890: 21.4 | G890: 75.5 | H890: 14.2
A891: 45864.923 | B891: 540 | C891: 18.2 | D891: 60.1 | E891: 9.3 | F891: 19.3 | G891: 81.4 | H891: 13.5
A892: 45865.007 | B892: 525 | C892: 15.9 | D892: 64.8 | E892: 8.8 | F892: 17.6 | G892: 85.5 | H892: 12.8
A893: 45865.09 | B893: 525 | C893: 14.9 | D893: 69.2 | E893: 8.8 | F893: 16.6 | G893: 88.2 | H893: 12.5
A894: 45865.173 | B894: 525 | C894: 18.2 | D894: 79.7 | E894: 12.4 | F894: 21 | G894: 83.4 | H894: 15.3
A895: 45865.257 | B895: 2145 | C895: 27.6 | D895: 70.6 | E895: 18.8 | F895: 29.7 | G895: 57.1 | H895: 17.1
A896: 45865.34 | B896: 2415 | C896: 38.1 | D896: 38.6 | E896: 17.9 | F896: 30.6 | G896: 49.8 | H896: 15.6
A897: 45865.423 | B897: 2985 | C897: 41.5 | D897: 32.1 | E897: 17.7 | F897: 28.2 | G897: 53 | H897: 14.6
A898: 45865.507 | B898: 2460 | C898: 44.3 | D898: 23.4 | E898: 14.8 | F898: 27.1 | G898: 49.9 | H898: 12.9
... A1018: 45875.51 | B1018: 2190 | C1018: 29.5 | D1018: 36.1 | E1018: 10.7 | F1018: 19.5 | G1018: 57.7 | H1018: 9.7
A1019: 45875.51 | B1019: 2190 | C1019: 29.5 | D1019: 36.1 | E1019: 10.7 | F1019: 19.5 | G1019: 57.7 | H1019: 9.7 | I1019: YES
A1020: 45875.593 | B1020: 1875 | C1020: 28.1 | D1020: 33.4 | E1020: 9.1 | F1020: 18.6 | G1020: 54.6 | H1020: 8.7
A1021: 45875.676 | B1021: 1080 | C1021: 24.1 | D1021: 37.4 | E1021: 8.2 | F1021: 17.7 | G1021: 60.1 | H1021: 9.1
A1022: 45875.759 | B1022: 525 | C1022: 18.4 | D1022: 46.8 | E1022: 7.4 | F1022: 16 | G1022: 70.6 | H1022: 9.6
A1023: 45875.843 | B1023: 540 | C1023: 15.2 | D1023: 56.5 | E1023: 7.3 | F1023: 14.7 | G1023: 81.5 | H1023: 10.3
A1024: 45875.926 | B1024: 525 | C1024: 14 | D1024: 63.6 | E1024: 7.7 | F1024: 12.8 | G1024: 89.6 | H1024: 10
A1025: 45876.009 | B1025: 540 | C1025: 12.7 | D1025: 66.1 | E1025: 7.4 | F1025: 12.4 | G1025: 92.5 | H1025: 10.1
A1026: 45876.093 | B1026: 525 | C1026: 10.6 | D1026: 71.6 | E1026: 7 | F1026: 11.2 | G1026: 94.7 | H1026: 9.6
...

Sheet Katto 3
A1: Timestamp | B1: Fan speed (rpm) | C1: Outdoor temp (°C) | D1: Outdoor RH (%) | E1: Outdoor abs. humidity (g/m³) | F1: Indoor temp (°C) | G1: Indoor RH (%) | H1: Indoor abs. humidity (g/m³) | I1: Duplicate of previous row | J1: Indoor reading missing | K1: Outdoor reading missing
A2: 45790.669 | B2: 1110 | J2: YES | K2: YES
A3: 45790.711 | B3: 1110 | J3: YES | K3: YES
A4: 45790.753 | B4: 1110 | J4: YES | K4: YES
A5: 45790.795 | B5: 1080 | J5: YES | K5: YES
A6: 45790.844 | B6: 3285 | C6: 11.7 | D6: 37.7 | E6: 3.9 | F6: 10.4 | G6: 61 | H6: 5.9
A7: 45790.927 | B7: 1950 | C7: 11.3 | D7: 56.2 | E7: 5.7 | F7: 9.3 | G7: 68.6 | H7: 6.2
A8: 45791.011 | B8: 1980 | C8: 10.4 | D8: 61.3 | E8: 5.9 | F8: 8.7 | G8: 74 | H8: 6.4
A9: 45791.094 | B9: 1830 | C9: 9 | D9: 68.6 | E9: 6 | F9: 7.5 | G9: 79.4 | H9: 6.4
A10: 45791.177 | B10: 930 | C10: 10.5 | D10: 74.8 | E10: 7.3 | F10: 7.5 | G10: 80 | H10: 6.4
A11: 45791.26 | B11: 975 | C11: 11.9 | D11: 57.9 | E11: 6.1 | F11: 6.2 | G11: 74.5 | H11: 5.5
A12: 45791.344 | B12: 510 | C12: 20.1 | D12: 50.4 | E12: 8.8 | F12: 9.2 | G12: 48.7 | H12: 4.3
A13: 45791.428 | B13: 495 | C13: 23 | D13: 31.6 | E13: 6.5 | F13: 9.5 | G13: 38.3 | H13: 3.5
A14: 45791.511 | B14: 570 | C14: 20.9 | D14: 23.2 | E14: 4.2 | F14: 9 | G14: 39.4 | H14: 3.5
A15: 45791.595 | B15: 3285 | C15: 12.1 | D15: 27.6 | E15: 3 | F15: 6.7 | G15: 56.1 | H15: 4.3
A16: 45791.678 | B16: 2025 | C16: 10.1 | D16: 49.1 | E16: 4.6 | F16: 5.7 | G16: 71.1 | H16: 5.1
A17: 45791.761 | B17: 2100 | C17: 7.8 | D17: 56.7 | E17: 4.6 | F17: 4.4 | G17: 78.4 | H17: 5.1
... A85: 45797.431 | B85: 645 | C85: 46.1 | D85: 12.9 | E85: 8.9 | F85: 19.9 | G85: 32.6 | H85: 5.6
A86: 45797.431 | B86: 645 | C86: 46.1 | D86: 12.9 | E86: 8.9 | F86: 19.9 | G86: 32.6 | H86: 5.6 | I86: YES
A87: 45797.515 | B87: 3165 | C87: 29 | D87: 16.8 | E87: 4.8 | F87: 17.5 | G87: 41.1 | H87: 6.1
A88: 45797.598 | B88: 1830 | C88: 18.7 | D88: 30.2 | E88: 4.8 | F88: 16.7 | G88: 35.7 | H88: 5.1
A89: 45797.681 | B89: 1245 | C89: 16 | D89: 31.6 | E89: 4.3 | F89: 15.3 | G89: 30.8 | H89: 4
A90: 45797.764 | B90: 2325 | C90: 13.7 | D90: 32.1 | E90: 3.8 | F90: 12.8 | G90: 38.7 | H90: 4.3
A91: 45797.848 | B91: 2760 | C91: 9.7 | D91: 36.6 | E91: 3.4 | F91: 9.6 | G91: 44 | H91: 4
A92: 45797.931 | B92: 2685 | C92: 6.4 | D92: 42.5 | E92: 3.2 | F92: 6.3 | G92: 50.3 | H92: 3.7
A93: 45798.015 | B93: 2070 | C93: 4.2 | D93: 53.1 | E93: 3.4 | F93: 4.6 | G93: 57.8 | H93: 3.8
A94: 45798.098 | B94: 1785 | C94: 3.3 | D94: 58.7 | E94: 3.6 | F94: 3.5 | G94: 63 | H94: 3.9
A95: 45798.182 | B95: 495 | C95: 13.9 | D95: 69.1 | E95: 8.3 | F95: 11.1 | G95: 48.7 | H95: 4.9
A96: 45798.266 | B96: 585 | C96: 35.2 | D96: 35.5 | E96: 14.2 | F96: 17.9 | G96: 33.5 | H96: 5.1
A97: 45798.349 | B97: 600 | C97: 40.9 | D97: 16.5 | E97: 8.8 | F97: 18.3 | G97: 29.8 | H97: 4.7
A98: 45798.433 | B98: 1815 | C98: 29.5 | D98: 14.3 | E98: 4.2 | F98: 13.7 | G98: 37.2 | H98: 4.4
... A610: 45841.353 | B610: 2070 | C610: 27.9 | D610: 46.1 | E610: 12.5 | F610: 20.5 | G610: 64.1 | H610: 11.4
A611: 45841.353 | B611: 2070 | C611: 27.9 | D611: 46.1 | E611: 12.5 | F611: 20.5 | G611: 64.1 | H611: 11.4 | I611: YES
A612: 45841.436 | B612: 1545 | C612: 32.9 | D612: 29.8 | E612: 10.6 | F612: 21.1 | G612: 58.2 | H612: 10.7
A613: 45841.52 | B613: 1335 | C613: 29.6 | D613: 33.7 | E613: 10 | F613: 20.6 | G613: 58.9 | H613: 10.5
A614: 45841.604 | B614: 510 | C614: 24.1 | D614: 44 | E614: 9.6 | F614: 19.9 | G614: 76.3 | H614: 13.1
A615: 45841.687 | B615: 1620 | C615: 21.7 | D615: 65.6 | E615: 12.5 | F615: 18.6 | G615: 78 | H615: 12.4
A616: 45841.77 | B616: 1350 | C616: 18.7 | D616: 65.8 | E616: 10.5 | F616: 16.9 | G616: 76.6 | H616: 11
A617: 45841.853 | B617: 1710 | C617: 14.6 | D617: 74.9 | E617: 9.4 | F617: 13.8 | G617: 76.9 | H617: 9.2
A618: 45841.937 | B618: 1575 | C618: 14.5 | D618: 74.8 | E618: 9.3 | F618: 12.7 | G618: 84 | H618: 9.3
...

Sheet Katto 4
A1: Timestamp | B1: Fan speed (rpm) | C1: Outdoor temp (°C) | D1: Outdoor RH (%) | E1: Outdoor abs. humidity (g/m³) | F1: Indoor temp (°C) | G1: Indoor RH (%) | H1: Indoor abs. humidity (g/m³) | I1: Duplicate of previous row | J1: Indoor reading missing | K1: Outdoor reading missing
A2: 45826.755 | B2: 1125 | J2: YES | K2: YES
A3: 45826.852 | B3: 1110 | J3: YES | K3: YES
A4: 45826.894 | B4: 1095 | J4: YES | K4: YES
A5: 45827.13 | B5: 1830 | C5: 10.4 | D5: 87.5 | E5: 8.4 | F5: 10.1 | G5: 85.3 | H5: 8.1
A6: 45827.214 | B6: 2025 | C6: 13.3 | D6: 80.9 | E6: 9.3 | F6: 11.3 | G6: 84.1 | H6: 8.6
A7: 45827.298 | B7: 2025 | C7: 19.1 | D7: 61.1 | E7: 10 | F7: 13.7 | G7: 77.6 | H7: 9.2
A8: 45827.38 | B8: 1725 | C8: 24.3 | D8: 43.9 | E8: 9.7 | F8: 15.9 | G8: 70.3 | H8: 9.5
A9: 45827.464 | B9: 750 | C9: 19.6 | D9: 49.9 | E9: 8.4 | F9: 14.5 | G9: 79.5 | H9: 9.9
A10: 45827.548 | B10: 1050 | C10: 17.5 | D10: 61 | E10: 9.1 | F10: 14.4 | G10: 81.4 | H10: 10.1
A11: 45827.631 | B11: 1185 | C11: 16.7 | D11: 66.9 | E11: 9.5 | F11: 14.2 | G11: 83.5 | H11: 10.2
A12: 45827.714 | B12: 1410 | C12: 15.4 | D12: 75.9 | E12: 10 | F12: 13.8 | G12: 86.1 | H12: 10.3
A13: 45827.798 | B13: 1365 | C13: 13.6 | D13: 80.3 | E13: 9.4 | F13: 13.5 | G13: 84.3 | H13: 9.9
A14: 45827.881 | B14: 1335 | C14: 12.9 | D14: 84.9 | E14: 9.6 | F14: 12.5 | G14: 90.5 | H14: 9.9
A15: 45827.964 | B15: 1470 | C15: 12.3 | D15: 85.8 | E15: 9.3 | F15: 12 | G15: 88.8 | H15: 9.5
A16: 45828.048 | B16: 1530 | C16: 11.8 | D16: 86 | E16: 9 | F16: 11.8 | G16: 86.3 | H16: 9.1
... A4746: 46224.991 | B4746: 1560 | C4746: 11.4 | D4746: 85.9 | E4746: 8.8 | F4746: 10.7 | G4746: 90.4 | H4746: 8.9
A4747: 46225.074 | B4747: 1545 | F4747: 10.5 | G4747: 91.2 | H4747: 8.8 | K4747: YES
A4748: 46225.157 | B4748: 1545 | F4748: 10.7 | G4748: 92 | H4748: 9 | K4748: YES
A4749: 46225.24 | B4749: 2145 | C4749: 14 | D4749: 86.7 | E4749: 10.5 | F4749: 11.8 | G4749: 89.5 | H4749: 9.4
A4750: 46225.323 | B4750: 2310 | C4750: 20.4 | D4750: 63.3 | E4750: 11.2 | F4750: 14.4 | G4750: 79.9 | H4750: 9.9
A4751: 46225.407 | B4751: 2820 | C4751: 35 | D4751: 27.8 | E4751: 11 | F4751: 19.2 | G4751: 56.2 | H4751: 9.3
A4752: 46225.49 | B4752: 2295 | C4752: 40.2 | D4752: 17 | E4752: 8.8 | F4752: 19.9 | G4752: 45.6 | H4752: 7.8
A4753: 46225.573 | B4753: 2010 | C4753: 38.3 | D4753: 16.5 | E4753: 7.7 | F4753: 19 | G4753: 44.7 | H4753: 7.3
A4754: 46225.657 | B4754: 1035 | C4754: 33.8 | D4754: 18.7 | E4754: 7 | F4754: 19.5 | G4754: 46.3 | H4754: 7.8
A4755: 46225.741 | B4755: 540 | C4755: 21.9 | D4755: 30 | E4755: 5.8 | F4755: 16.9 | G4755: 59.5 | H4755: 8.6
A4756: 46225.824 | B4756: 525 | C4756: 16.5 | D4756: 41 | E4756: 5.8 | F4756: 15.3 | G4756: 66.3 | H4756: 8.7
A4757: 46225.907 | B4757: 525 | C4757: 13.5 | D4757: 56.9 | E4757: 6.7 | F4757: 13.9 | G4757: 73.6 | H4757: 8.8
A4758: 46225.991 | B4758: 570 | C4758: 13.1 | D4758: 67.7 | E4758: 7.7 | F4758: 13.6 | G4758: 79.7 | H4758: 9.4
A4759: 46226.074 | B4759: 945 | C4759: 12.6 | D4759: 74.3 | E4759: 8.2 | F4759: 12.7 | G4759: 82.7 | H4759: 9.2
A4760: 46226.158 | B4760: 1590 | C4760: 12.9 | D4760: 83.3 | E4760: 9.4 | F4760: 12.3 | G4760: 86.2 | H4760: 9.4
... A5352: 46276.167 | B5352: 945 | C5352: 7.7 | D5352: 89.9 | E5352: 7.3 | F5352: 8 | G5352: 98.7 | H5352: 8.2

Sheet Viherkatto 1
A1: Timestamp | B1: Fan speed (rpm) | C1: Outdoor temp (°C) | D1: Outdoor RH (%) | E1: Outdoor abs. humidity (g/m³) | F1: Indoor temp (°C) | G1: Indoor RH (%) | H1: Indoor abs. humidity (g/m³) | I1: Duplicate of previous row | J1: Indoor reading missing | K1: Outdoor reading missing
A2: 45790.72 | B2: 1110 | J2: YES | K2: YES
A3: 45790.761 | B3: 1095 | J3: YES | K3: YES
A4: 45790.803 | B4: 1095 | J4: YES | K4: YES
A5: 45790.845 | B5: 1095 | J5: YES | K5: YES
A6: 45790.894 | B6: 3315 | C6: 10.5 | D6: 63.5 | E6: 6.2 | J6: YES
A7: 45790.978 | B7: 3315 | C7: 10.2 | D7: 67.5 | E7: 6.4 | J7: YES
A8: 45791.062 | B8: 3330 | C8: 9.3 | D8: 73.7 | E8: 6.6 | J8: YES
A9: 45791.145 | B9: 3300 | C9: 8.4 | D9: 76.4 | E9: 6.5 | J9: YES
A10: 45791.229 | B10: 3315 | C10: 8.8 | D10: 71.2 | E10: 6.2 | J10: YES
A11: 45791.313 | B11: 3300 | C11: 8.9 | D11: 60.3 | E11: 5.3 | J11: YES
A12: 45791.396 | B12: 3330 | C12: 11 | D12: 39.3 | E12: 3.9 | J12: YES
A13: 45791.563 | B13: 3345 | C13: 9.3 | D13: 52.7 | E13: 4.7 | J13: YES
A14: 45791.647 | B14: 3300 | C14: 7 | D14: 66.1 | E14: 5.1 | J14: YES
A15: 45791.731 | B15: 3345 | C15: 6.1 | D15: 71.7 | E15: 5.2 | J15: YES
A16: 45791.814 | B16: 3300 | C16: 5.1 | D16: 80.4 | E16: 5.5 | J16: YES
A17: 45791.897 | B17: 3300 | C17: 4.7 | D17: 82.7 | E17: 5.5 | J17: YES
... A334: 45818.59 | B334: 3375 | C334: 17.9 | D334: 50.9 | E334: 7.8 | J334: YES
A335: 45818.59 | B335: 3375 | C335: 17.9 | D335: 50.9 | E335: 7.8 | I335: YES | J335: YES
A336: 45818.673 | B336: 3390 | C336: 16.7 | D336: 64.7 | E336: 9.2 | J336: YES
A337: 45818.757 | B337: 3375 | C337: 14 | D337: 76.6 | E337: 9.2 | J337: YES
A338: 45818.84 | B338: 3375 | C338: 11.9 | D338: 86.8 | E338: 9.2 | J338: YES
A339: 45818.923 | B339: 3330 | C339: 10.4 | D339: 92.1 | E339: 8.9 | J339: YES
A340: 45819.007 | B340: 3315 | C340: 9.4 | D340: 93.1 | E340: 8.4 | J340: YES
A341: 45819.091 | B341: 3360 | C341: 9.1 | D341: 92.6 | E341: 8.2 | J341: YES
A342: 45819.174 | B342: 3330 | C342: 11.1 | D342: 95.8 | E342: 9.6 | J342: YES
A343: 45819.257 | B343: 3315 | C343: 12.3 | D343: 93.2 | E343: 10.1 | J343: YES
A344: 45819.34 | B344: 3330 | C344: 12.1 | D344: 94.3 | E344: 10.1 | J344: YES
A345: 45819.423 | B345: 3375 | C345: 11.6 | D345: 97.7 | E345: 10.2 | J345: YES
A346: 45819.507 | B346: 3390 | C346: 12.5 | D346: 97.4 | E346: 10.7 | J346: YES
A347: 45819.59 | B347: 3345 | C347: 12.6 | D347: 98.3 | E347: 10.9 | J347: YES
... A429: 45826.591 | B429: 3420 | C429: 15.9 | D429: 88.6 | E429: 12 | J429: YES
A430: 45826.675 | B430: 1080 | C430: 15.8 | D430: 85.4 | E430: 11.5 | F430: 20.3 | G430: 59.3 | H430: 10.4
A431: 45826.758 | B431: 945 | C431: 14.8 | D431: 83.6 | E431: 10.6 | F431: 18.7 | G431: 58.5 | H431: 9.4
A432: 45826.841 | B432: 915 | C432: 13.7 | D432: 80.3 | E432: 9.5 | F432: 16.6 | G432: 58.7 | H432: 8.3
A433: 45826.924 | B433: 750 | C433: 12.6 | D433: 80.6 | E433: 8.9 | F433: 14.5 | G433: 60.8 | H433: 7.6
A434: 45827.007 | B434: 840 | C434: 11.3 | D434: 82.6 | E434: 8.4 | F434: 12.9 | G434: 65 | H434: 7.3
A435: 45827.091 | B435: 765 | C435: 10.3 | D435: 87.3 | E435: 8.4 | F435: 11.5 | G435: 69.3 | H435: 7.2
A436: 45827.175 | B436: 915 | C436: 11 | D436: 87.4 | E436: 8.7 | F436: 10.9 | G436: 77.9 | H436: 7.7
A437: 45827.258 | B437: 1215 | C437: 12.8 | D437: 84.6 | E437: 9.5 | F437: 11.7 | G437: 84.6 | H437: 8.8
...

Sheet Viherkatto 2
A1: Timestamp | B1: Fan speed (rpm) | C1: Outdoor temp (°C) | D1: Outdoor RH (%) | E1: Outdoor abs. humidity (g/m³) | F1: Indoor temp (°C) | G1: Indoor RH (%) | H1: Indoor abs. humidity (g/m³) | I1: Duplicate of previous row | J1: Indoor reading missing | K1: Outdoor reading missing
A2: 45790.676 | B2: 0 | J2: YES | K2: YES
A3: 45790.718 | B3: 0 | J3: YES | K3: YES
A4: 45790.76 | B4: 0 | J4: YES | K4: YES
A5: 45790.801 | B5: 0 | J5: YES | K5: YES
A6: 45790.851 | B6: 0 | C6: 15.3 | D6: 35.2 | E6: 4.6 | F6: 10.8 | G6: 59.2 | H6: 5.8
A7: 45790.934 | B7: 0 | C7: 13.4 | D7: 46.8 | E7: 5.4 | F7: 9.9 | G7: 65.2 | H7: 6.1
A8: 45791.017 | B8: 0 | C8: 12.1 | D8: 53.4 | E8: 5.7 | F8: 9.2 | G8: 71.7 | H8: 6.4
A9: 45791.101 | B9: 0 | C9: 11.1 | D9: 57.4 | E9: 5.8 | F9: 8.1 | G9: 76.2 | H9: 6.3
A10: 45791.184 | B10: 0 | C10: 10.1 | D10: 60.4 | E10: 5.7 | F10: 8 | G10: 76 | H10: 6.3
A11: 45791.268 | B11: 0 | C11: 10.1 | D11: 57.8 | E11: 5.5 | F11: 6.6 | G11: 71.2 | H11: 5.4
A12: 45791.351 | B12: 0 | C12: 10.6 | D12: 52.9 | E12: 5.2 | F12: 9.6 | G12: 44.8 | H12: 4.1
A13: 45791.434 | B13: 0 | C13: 11.8 | D13: 45.2 | E13: 4.8 | F13: 10.2 | G13: 34.1 | H13: 3.2
A14: 45791.517 | B14: 0 | C14: 14 | D14: 38.9 | E14: 4.7 | F14: 9.9 | G14: 36.8 | H14: 3.4
A15: 45791.6 | B15: 0 | C15: 15.7 | D15: 37.1 | E15: 5 | F15: 7.3 | G15: 54 | H15: 4.3
A16: 45791.683 | B16: 0 | C16: 14.3 | D16: 37.2 | E16: 4.6 | F16: 6.4 | G16: 66 | H16: 4.9
A17: 45791.767 | B17: 0 | C17: 12.3 | D17: 42 | E17: 4.6 | F17: 5 | G17: 75.2 | H17: 5.1
... A2509: 46000.599 | B2509: 0 | C2509: 8.6 | D2509: 84.1 | E2509: 7.2 | F2509: 3.9 | G2509: 100 | H2509: 6.3
A2510: 46000.682 | B2510: 0 | C2510: 8.1 | D2510: 79.6 | E2510: 6.6 | J2510: YES
A2511: 46000.766 | B2511: 0 | C2511: 7.2 | D2511: 77.9 | E2511: 6.1 | F2511: 2.3 | G2511: 100 | H2511: 5.7
A2512: 46000.85 | B2512: 0 | C2512: 6.4 | D2512: 79.7 | E2512: 5.9 | F2512: 2.1 | G2512: 100 | H2512: 5.6
A2513: 46000.933 | B2513: 0 | C2513: 5.9 | D2513: 79.4 | E2513: 5.7 | F2513: 1.3 | G2513: 100 | H2513: 5.3
A2514: 46001.017 | B2514: 0 | C2514: 5.4 | D2514: 78.3 | E2514: 5.5 | F2514: 0.7 | G2514: 100 | H2514: 5.1
A2515: 46001.1 | B2515: 0 | C2515: 5.1 | D2515: 78.2 | E2515: 5.3 | F2515: 0 | G2515: 100 | H2515: 4.8
A2516: 46001.183 | B2516: 0 | C2516: 4.4 | D2516: 76.4 | E2516: 5 | F2516: -0.4 | G2516: 100 | H2516: 4.7
A2517: 46001.267 | B2517: 0 | C2517: 3.7 | D2517: 77.5 | E2517: 4.8 | F2517: -0.9 | G2517: 100 | H2517: 4.6
A2518: 46001.35 | B2518: 0 | C2518: 3.4 | D2518: 78.5 | E2518: 4.8 | F2518: -0.6 | G2518: 100 | H2518: 4.7
A2519: 46001.433 | B2519: 0 | C2519: 3.3 | D2519: 80.5 | E2519: 4.9 | F2519: -0.3 | G2519: 100 | H2519: 4.8
A2520: 46001.517 | B2520: 0 | C2520: 3.3 | D2520: 82.1 | E2520: 5 | F2520: -0.1 | G2520: 100 | H2520: 4.8
A2521: 46001.6 | B2521: 0 | C2521: 3.5 | D2521: 83.5 | E2521: 5.1 | F2521: 2.3 | G2521: 100 | H2521: 5.7
A2522: 46001.684 | B2522: 0 | C2522: 3.8 | D2522: 88 | E2522: 5.5 | F2522: 4.3 | G2522: 100 | H2522: 6.5
... A5795: 46276.231 | B5795: 0 | C5795: 9.9 | D5795: 81.1 | E5795: 7.6 | F5795: 9.4 | G5795: 95.4 | H5795: 8.6

Sheet Hallin alapohja
A1: Timestamp | B1: Fan speed (rpm) | C1: Outdoor temp (°C) | D1: Outdoor RH (%) | E1: Outdoor abs. humidity (g/m³) | F1: Indoor temp (°C) | G1: Indoor RH (%) | H1: Indoor abs. humidity (g/m³) | I1: Duplicate of previous row | J1: Indoor reading missing | K1: Outdoor reading missing
A2: 45791.258 | B2: 855 | J2: YES | K2: YES
A3: 45791.307 | B3: 2370 | C3: 8.3 | D3: 86.4 | E3: 7.3 | F3: 8.1 | G3: 64.8 | H3: 5.4
A4: 45791.39 | B4: 2595 | C4: 8.4 | D4: 79.1 | E4: 6.7 | F4: 9.7 | G4: 38.5 | H4: 3.5
A5: 45791.473 | B5: 2565 | C5: 8.5 | D5: 75.1 | E5: 6.4 | F5: 10.4 | G5: 35.9 | H5: 3.5
A6: 45791.557 | B6: 2430 | C6: 8.5 | D6: 75.7 | E6: 6.5 | F6: 9.1 | G6: 53.4 | H6: 4.7
A7: 45791.64 | B7: 2190 | C7: 8.4 | D7: 80 | E7: 6.8 | F7: 6.8 | G7: 69.2 | H7: 5.3
A8: 45791.724 | B8: 2325 | C8: 8.3 | D8: 83.9 | E8: 7.1 | F8: 5.5 | G8: 75.2 | H8: 5.3
A9: 45791.807 | B9: 2070 | C9: 8.2 | D9: 85.5 | E9: 7.2 | F9: 4.3 | G9: 87.3 | H9: 5.7
A10: 45791.891 | B10: 2220 | C10: 8.2 | D10: 87 | E10: 7.3 | F10: 3.8 | G10: 86.7 | H10: 5.4
A11: 45791.974 | B11: 2190 | C11: 8.1 | D11: 88 | E11: 7.3 | F11: 3.5 | G11: 88.7 | H11: 5.5
A12: 45792.057 | B12: 2025 | C12: 8.1 | D12: 88.5 | E12: 7.4 | F12: 4 | G12: 91.9 | H12: 5.8
A13: 45792.141 | B13: 1440 | C13: 8.2 | D13: 89.3 | E13: 7.5 | F13: 5.6 | G13: 98.8 | H13: 7
A14: 45792.224 | B14: 1455 | C14: 8.3 | D14: 89.5 | E14: 7.5 | F14: 7.8 | G14: 87 | H14: 7.1
... A98: 45799.309 | B98: 1710 | C98: 9.2 | D98: 89 | E98: 7.9 | F98: 12.9 | G98: 62.2 | H98: 7
A99: 45799.309 | B99: 1710 | C99: 9.2 | D99: 89 | E99: 7.9 | F99: 12.9 | G99: 62.2 | H99: 7 | I99: YES
A100: 45799.392 | B100: 1680 | C100: 9.2 | D100: 90.1 | E100: 8 | F100: 13.6 | G100: 60.5 | H100: 7.1
A101: 45799.475 | B101: 1710 | C101: 9.3 | D101: 90.6 | E101: 8.1 | F101: 15.1 | G101: 55.2 | H101: 7.1
A102: 45799.559 | B102: 1590 | C102: 9.3 | D102: 91.2 | E102: 8.2 | F102: 13.8 | G102: 62.2 | H102: 7.4
A103: 45799.642 | B103: 1860 | C103: 9.3 | D103: 91.5 | E103: 8.2 | F103: 14.8 | G103: 55.2 | H103: 7
A104: 45799.726 | B104: 1875 | C104: 9.4 | D104: 91.1 | E104: 8.2 | F104: 14.8 | G104: 54.9 | H104: 7
A105: 45799.892 | B105: 1800 | C105: 9.3 | D105: 91.9 | E105: 8.3 | F105: 10.7 | G105: 72.4 | H105: 7.1
A106: 45799.976 | B106: 1335 | C106: 9.3 | D106: 92.9 | E106: 8.3 | F106: 10.7 | G106: 81.9 | H106: 8
A107: 45800.06 | B107: 1245 | C107: 9.3 | D107: 95 | E107: 8.5 | F107: 11 | G107: 84.3 | H107: 8.4
A108: 45800.142 | B108: 1080 | C108: 9.3 | D108: 97.2 | E108: 8.7 | F108: 11 | G108: 89.8 | H108: 9
A109: 45800.226 | B109: 915 | C109: 9.3 | D109: 97.8 | E109: 8.8 | F109: 10.6 | G109: 96.8 | H109: 9.4
A110: 45800.31 | B110: 1095 | C110: 9.2 | D110: 97.7 | E110: 8.7 | F110: 9.9 | G110: 95.7 | H110: 8.9
A111: 45800.393 | B111: 1020 | C111: 9.2 | D111: 97.8 | E111: 8.7 | F111: 10.4 | G111: 95 | H111: 9.2
... A344: 45820.147 | B344: 900 | C344: 9.9 | D344: 100 | E344: 9.3 | F344: 11.2 | G344: 100 | H344: 10.1
A345: 45820.231 | B345: 900 | C345: 10 | D345: 100 | E345: 9.4 | J345: YES
A346: 45820.314 | B346: 810 | C346: 10 | D346: 100 | E346: 9.4 | F346: 11.6 | G346: 100 | H346: 10.4
A347: 45820.397 | B347: 615 | C347: 10 | D347: 100 | E347: 9.4 | F347: 12.7 | G347: 100 | H347: 11.1
A348: 45820.479 | B348: 525 | C348: 10.1 | D348: 100 | E348: 9.5 | F348: 14.3 | G348: 93.4 | H348: 11.5
A349: 45820.562 | B349: 765 | C349: 10.2 | D349: 100 | E349: 9.5 | F349: 15.3 | G349: 80.9 | H349: 10.6
A350: 45820.646 | B350: 900 | C350: 10.3 | D350: 100 | E350: 9.6 | F350: 16.4 | G350: 73.7 | H350: 10.3
A351: 45820.729 | B351: 675 | C351: 10.2 | D351: 100 | E351: 9.5 | F351: 15.6 | G351: 83 | H351: 11
A352: 45820.813 | B352: 780 | C352: 10.1 | D352: 100 | E352: 9.5 | F352: 14.2 | G352: 86 | H352: 10.5
A353: 45820.896 | B353: 795 | C353: 10.1 | D353: 100 | E353: 9.5 | F353: 12.9 | G353: 92.8 | H353: 10.5
A354: 45820.98 | B354: 960 | C354: 10.1 | D354: 100 | E354: 9.5 | F354: 11.7 | G354: 95.4 | H354: 10
A355: 45821.063 | B355: 1365 | C355: 10 | D355: 100 | E355: 9.4 | F355: 10.8 | G355: 90.6 | H355: 9
...
